============================= test session starts =============================
platform win32 -- Python 3.7.4, pytest-5.1.2, py-1.8.0, pluggy-0.13.0
rootdir: C:\Users\RoffyMonsta\DevOps\lab_2
collected 4 items

tests\tests.py ..F.                                                      [100%]

================================== FAILURES ===================================
__________________________ TestClass.test_home_work ___________________________

self = <tests.tests.TestClass testMethod=test_home_work>

    def test_home_work(self):
        # Ваш захист
        self.assertTrue(home_work(self.date_pm) == 'PM')
>       self.assertTrue(home_work(self.date_am) == 'AM')
E       AssertionError: False is not true

tests\tests.py:29: AssertionError
---------------------------- Captured stdout call -----------------------------
_________________________
	Good Evening 	
_________________________
_________________________
	 Good Morning 	
____________________
========================= 1 failed, 3 passed in 1.01s =========================

-----------------------------------------------------

========================================
Результат без параметрів: 
No URL passed to function
========================================
Результат з правильною URL: 
Time is:  05:42:47 PM
_________________________
	Good Evening 	
_________________________
Date is:  09-18-2019
